<?xml version="1.0" ?>
<!-- =================================================================================== -->
<!-- |    This document was autogenerated by xacro from /home/han/fire_ws/install/fire_description/share/fire_description/urdf/fire_robot.xacro | -->
<!-- |    EDITING THIS FILE BY HAND IS NOT RECOMMENDED                                 | -->
<!-- =================================================================================== -->
<robot name="fire_robot">
  <!-- xacro 루트 링크에 inertial 있으면 경고 띄움. dummy용-->
  <link name="base_footprint"/>
  <joint name="base_footprint_joint" type="fixed">
    <parent link="base_footprint"/>
    <child link="base_link"/>
    <origin rpy="0 0 0" xyz="0 0 0"/>
  </joint>
  <!-- ========== base_link (루트) ========== -->
  <link name="base_link">
    <inertial>
      <origin rpy="0 0 0" xyz="0 0 0"/>
      <mass value="6.0"/>
      <inertia ixx="0.02" ixy="0" ixz="0" iyy="0.02" iyz="0" izz="0.02"/>
    </inertial>
    <visual>
      <origin rpy="0 0 0" xyz="0 0 0"/>
      <geometry>
        <mesh filename="package://fire_description/meshes/base_link_Body1.obj" scale="0.001 0.001 0.001"/>
      </geometry>
    </visual>
    <collision>
      <origin rpy="0 0 0" xyz="0 0 0"/>
      <geometry>
        <mesh filename="package://fire_description/meshes/base_link_Body1.obj" scale="0.001 0.001 0.001"/>
      </geometry>
    </collision>
  </link>
  <!-- ========== ARM ========== -->
  <joint name="arm_joint" type="revolute">
    <origin rpy="0 0 0" xyz="0.2765 0 0"/>
    <parent link="base_link"/>
    <child link="arm"/>
    <axis xyz="0 1 0"/>
    <limit effort="50" lower="-0.5" upper="0.5" velocity="1.0"/>
    <!-- dynamic damping -->
    <dynamics damping="0.05" friction="0.2"/>
  </joint>
  <link name="arm">
    <inertial>
      <origin rpy="0 0 0" xyz="0 0 0"/>
      <mass value="0.4"/>
      <inertia ixx="0.001" ixy="0" ixz="0" iyy="0.001" iyz="0" izz="0.001"/>
    </inertial>
    <visual>
      <origin rpy="0 0 0" xyz="0 0 0"/>
      <geometry>
        <mesh filename="package://fire_description/meshes/arm_Body1.obj" scale="0.001 0.001 0.001"/>
      </geometry>
    </visual>
    <collision>
      <origin rpy="0 0 0" xyz="0 0 0"/>
      <geometry>
        <mesh filename="package://fire_description/meshes/arm_Body1.obj" scale="0.001 0.001 0.001"/>
      </geometry>
    </collision>
  </link>
  <!-- ========== BLADE ========== -->
  <joint name="blade_joint" type="continuous">
    <origin rpy="0 0 0" xyz="0. 0 0"/>
    <parent link="arm"/>
    <child link="blade"/>
    <axis xyz="0 1 0"/>
    <limit effort="5.0" velocity="200.0"/>
    <dynamics damping="0.01" friction="0.05"/>
  </joint>
  <link name="blade">
    <inertial>
      <origin rpy="0 0 0" xyz="0 0 0"/>
      <mass value="2.7"/>
      <inertia ixx="0.005" ixy="0" ixz="0" iyy="0.005" iyz="0" izz="0.005"/>
    </inertial>
    <visual>
      <origin rpy="0 0 0" xyz="0 0 0"/>
      <geometry>
        <mesh filename="package://fire_description/meshes/blade_Body1.obj" scale="0.001 0.001 0.001"/>
      </geometry>
    </visual>
    <collision>
      <origin rpy="0 0 0" xyz="0 0 0"/>
      <geometry>
        <mesh filename="package://fire_description/meshes/blade_Body1.obj" scale="0.001 0.001 0.001"/>
      </geometry>
    </collision>
  </link>
  <!-- ========== LEFT WHEELS (parent=base_link) ========== -->
  <joint name="left_wheel_1_joint" type="continuous">
    <origin rpy="0 0 0" xyz="0 0 0"/>
    <parent link="base_link"/>
    <child link="left_wheel1"/>
    <axis xyz="0 1 0"/>
    <dynamics damping="0.05" friction="0.0"/>
    <limit effort="5.0" velocity="0.26"/>
  </joint>
  <link name="left_wheel1">
    <inertial>
      <origin rpy="0 0 0" xyz="0 0 0"/>
      <mass value="2.5"/>
      <inertia ixx="0.002" ixy="0" ixz="0" iyy="0.002" iyz="0" izz="0.002"/>
    </inertial>
    <visual>
      <origin rpy="0 0 0" xyz="0 0 0"/>
      <geometry>
        <mesh filename="package://fire_description/meshes/left_wheel1_Body1.obj" scale="0.001 0.001 0.001"/>
      </geometry>
    </visual>
    <collision>
      <origin rpy="0 0 0" xyz="0 0 0"/>
      <geometry>
        <mesh filename="package://fire_description/meshes/left_wheel1_Body1.obj" scale="0.001 0.001 0.001"/>
      </geometry>
    </collision>
  </link>
  <joint name="left_wheel_2_joint" type="continuous">
    <origin rpy="0 0 0" xyz="0 0 0"/>
    <parent link="base_link"/>
    <child link="left_wheel2"/>
    <axis xyz="0 1 0"/>
    <dynamics damping="0.05" friction="0.0"/>
    <limit effort="5.0" velocity="0.26"/>
  </joint>
  <link name="left_wheel2">
    <inertial>
      <origin rpy="0 0 0" xyz="0 0 0"/>
      <mass value="2.5"/>
      <inertia ixx="0.002" ixy="0" ixz="0" iyy="0.002" iyz="0" izz="0.002"/>
    </inertial>
    <visual>
      <origin rpy="0 0 0" xyz="0 0 0"/>
      <geometry>
        <mesh filename="package://fire_description/meshes/left_wheel2_Body1.obj" scale="0.001 0.001 0.001"/>
      </geometry>
    </visual>
    <collision>
      <origin rpy="0 0 0" xyz="0 0 0"/>
      <geometry>
        <mesh filename="package://fire_description/meshes/left_wheel2_Body1.obj" scale="0.001 0.001 0.001"/>
      </geometry>
    </collision>
  </link>
  <joint name="left_wheel_3_joint" type="continuous">
    <origin rpy="0 0 0" xyz="0 0 0"/>
    <parent link="base_link"/>
    <child link="left_wheel3"/>
    <axis xyz="0 1 0"/>
    <dynamics damping="0.05" friction="0.0"/>
    <limit effort="5.0" velocity="0.26"/>
  </joint>
  <link name="left_wheel3">
    <inertial>
      <origin rpy="0 0 0" xyz="0 0 0"/>
      <mass value="2.5"/>
      <inertia ixx="0.002" ixy="0" ixz="0" iyy="0.002" iyz="0" izz="0.002"/>
    </inertial>
    <visual>
      <origin rpy="0 0 0" xyz="0 0 0"/>
      <geometry>
        <mesh filename="package://fire_description/meshes/left_wheel3_Body1.obj" scale="0.001 0.001 0.001"/>
      </geometry>
    </visual>
    <collision>
      <origin rpy="0 0 0" xyz="0 0 0"/>
      <geometry>
        <mesh filename="package://fire_description/meshes/left_wheel3_Body1.obj" scale="0.001 0.001 0.001"/>
      </geometry>
    </collision>
  </link>
  <!-- ========== RIGHT WHEELS ========== -->
  <joint name="right_wheel_1_joint" type="continuous">
    <origin rpy="0 0 0" xyz="0 0 0"/>
    <parent link="base_link"/>
    <child link="right_wheel1"/>
    <axis xyz="0 1 0"/>
    <dynamics damping="0.05" friction="0.0"/>
    <limit effort="5.0" velocity="0.26"/>
  </joint>
  <link name="right_wheel1">
    <inertial>
      <origin rpy="0 0 0" xyz="0 0 0"/>
      <mass value="2.5"/>
      <inertia ixx="0.002" ixy="0" ixz="0" iyy="0.002" iyz="0" izz="0.002"/>
    </inertial>
    <visual>
      <origin rpy="0 0 0" xyz="0 0 0"/>
      <geometry>
        <mesh filename="package://fire_description/meshes/right_wheel1_Body1.obj" scale="0.001 0.001 0.001"/>
      </geometry>
    </visual>
    <collision>
      <origin rpy="0 0 0" xyz="0 0 0"/>
      <geometry>
        <mesh filename="package://fire_description/meshes/right_wheel1_Body1.obj" scale="0.001 0.001 0.001"/>
      </geometry>
    </collision>
  </link>
  <joint name="right_wheel_2_joint" type="continuous">
    <origin rpy="0 0 0" xyz="0 0 0"/>
    <parent link="base_link"/>
    <child link="right_wheel2"/>
    <axis xyz="0 1 0"/>
    <dynamics damping="0.05" friction="0.0"/>
    <limit effort="5.0" velocity="0.26"/>
  </joint>
  <link name="right_wheel2">
    <inertial>
      <origin rpy="0 0 0" xyz="0 0 0"/>
      <mass value="2.5"/>
      <inertia ixx="0.002" ixy="0" ixz="0" iyy="0.002" iyz="0" izz="0.002"/>
    </inertial>
    <visual>
      <origin rpy="0 0 0" xyz="0 0 0"/>
      <geometry>
        <mesh filename="package://fire_description/meshes/right_wheel2_Body1.obj" scale="0.001 0.001 0.001"/>
      </geometry>
    </visual>
    <collision>
      <origin rpy="0 0 0" xyz="0 0 0"/>
      <geometry>
        <mesh filename="package://fire_description/meshes/right_wheel2_Body1.obj" scale="0.001 0.001 0.001"/>
      </geometry>
    </collision>
  </link>
  <joint name="right_wheel_3_joint" type="continuous">
    <origin rpy="0 0 0" xyz="0 0 0"/>
    <parent link="base_link"/>
    <child link="right_wheel3"/>
    <axis xyz="0 1 0"/>
    <dynamics damping="0.05" friction="0.0"/>
    <limit effort="5.0" velocity="0.26"/>
  </joint>
  <link name="right_wheel3">
    <inertial>
      <origin rpy="0 0 0" xyz="0 0 0"/>
      <mass value="2.5"/>
      <inertia ixx="0.002" ixy="0" ixz="0" iyy="0.002" iyz="0" izz="0.002"/>
    </inertial>
    <visual>
      <origin rpy="0 0 0" xyz="0 0 0"/>
      <geometry>
        <mesh filename="package://fire_description/meshes/right_wheel3_Body1.obj" scale="0.001 0.001 0.001"/>
      </geometry>
    </visual>
    <collision>
      <origin rpy="0 0 0" xyz="0 0 0"/>
      <geometry>
        <mesh filename="package://fire_description/meshes/right_wheel3_Body1.obj" scale="0.001 0.001 0.001"/>
      </geometry>
    </collision>
  </link>
  <!-- ros2_control 선언: 모던 Gazebo용 시스템 플러그인, gazebo classic 버전말고 ignition 버전으로!! -->
  <ros2_control name="GazeboSystem" type="system">
    <hardware>
      <plugin>gz_ros2_control/GazeboSimSystem</plugin>
    </hardware>
    <!-- Arm : position 명령-->
    <joint name="arm_joint">
      <command_interface name="position"/>
      <state_interface name="position"/>
      <state_interface name="velocity"/>
      <state_interface name="effort"/>
    </joint>
    <!-- Blade : velocity 명령-->
    <joint name="blade_joint">
      <command_interface name="velocity"/>
      <state_interface name="position"/>
      <state_interface name="velocity"/>
      <state_interface name="effort"/>
    </joint>
    <!-- Wheels : velocity 명령-->
    <joint name="left_wheel_1_joint">
      <command_interface name="velocity"/>
      <state_interface name="position"/>
      <state_interface name="velocity"/>
    </joint>
    <joint name="left_wheel_2_joint">
      <command_interface name="velocity"/>
      <state_interface name="position"/>
      <state_interface name="velocity"/>
    </joint>
    <joint name="left_wheel_3_joint">
      <command_interface name="velocity"/>
      <state_interface name="position"/>
      <state_interface name="velocity"/>
    </joint>
    <joint name="right_wheel_1_joint">
      <command_interface name="velocity"/>
      <state_interface name="position"/>
      <state_interface name="velocity"/>
    </joint>
    <joint name="right_wheel_2_joint">
      <command_interface name="velocity"/>
      <state_interface name="position"/>
      <state_interface name="velocity"/>
    </joint>
    <joint name="right_wheel_3_joint">
      <command_interface name="velocity"/>
      <state_interface name="position"/>
      <state_interface name="velocity"/>
    </joint>
  </ros2_control>
  <!-- Gazebo 플러그인: 컨트롤러 매니저와 YAML 연결; gazebo classic 버전말고 ignition 버전으로!! -->
  <gazebo>
    <plugin filename="libgz_ros2_control-system.so" name="gz_ros2_control">
      <parameters>&quot;/home/han/fire_ws/install/fire_bringup/share/fire_bringup/share/fire_bringup/config/controller.yaml&quot;</parameters>
    </plugin>
  </gazebo>
</robot>
